Workbook

Sheet motorcycles
A1: motorcycle_id | B1: brand | C1: model | D1: variant | E1: body_type | F1: segment_group | G1: video_collected | H1: status
A2: aprilia_rs_457_standard | B2: Aprilia | C2: RS 457 | D2: Standard | E2: Sport | F2: Premium/Performance ICE | G2: =IF(COUNTIFS(videos!$A:$A,A2,videos!$C:$C,"<>")>=1,"Yes","No") | H2: =IF(G2="Yes","Done","Not started")
A3: aprilia_rs_660_standard | B3: Aprilia | C3: RS 660 | D3: Standard | E3: Sport | F3: Premium/Performance ICE | G3: =IF(COUNTIFS(videos!$A:$A,A3,videos!$C:$C,"<>")>=1,"Yes","No") | H3: =IF(G3="Yes","Done","Not started")
A4: aprilia_tuono_660_standard | B4: Aprilia | C4: Tuono 660 | D4: Standard | E4: Naked/Street | F4: Premium/Performance ICE | G4: =IF(COUNTIFS(videos!$A:$A,A4,videos!$C:$C,"<>")>=1,"Yes","No") | H4: =IF(G4="Yes","Done","Not started")
A5: aprilia_tuareg_660_standard | B5: Aprilia | C5: Tuareg 660 | D5: Standard | E5: Adventure | F5: Premium/Performance ICE | G5: =IF(COUNTIFS(videos!$A:$A,A5,videos!$C:$C,"<>")>=1,"Yes","No") | H5: =IF(G5="Yes","Done","Not started")
A6: aprilia_rsv4_factory_standard | B6: Aprilia | C6: RSV4 Factory | D6: Standard | E6: Superbike | F6: Premium/Performance ICE | G6: =IF(COUNTIFS(videos!$A:$A,A6,videos!$C:$C,"<>")>=1,"Yes","No") | H6: =IF(G6="Yes","Done","Not started")
A7: aprilia_sr_125_standard | B7: Aprilia | C7: SR 125 | D7: Standard | E7: Scooter | F7: Mass-market ICE | G7: =IF(COUNTIFS(videos!$A:$A,A7,videos!$C:$C,"<>")>=1,"Yes","No") | H7: =IF(G7="Yes","Done","Not started")
A8: aprilia_sr_160_standard | B8: Aprilia | C8: SR 160 | D8: Standard | E8: Scooter | F8: Mass-market ICE | G8: =IF(COUNTIFS(videos!$A:$A,A8,videos!$C:$C,"<>")>=1,"Yes","No") | H8: =IF(G8="Yes","Done","Not started")
A9: aprilia_sxr_160_standard | B9: Aprilia | C9: SXR 160 | D9: Standard | E9: Scooter | F9: Premium/Performance ICE | G9: =IF(COUNTIFS(videos!$A:$A,A9,videos!$C:$C,"<>")>=1,"Yes","No") | H9: =IF(G9="Yes","Done","Not started")
A10: bajaj_ct_110x_standard | B10: Bajaj | C10: CT 110X | D10: Standard | E10: Commuter | F10: Mass-market ICE | G10: =IF(COUNTIFS(videos!$A:$A,A10,videos!$C:$C,"<>")>=1,"Yes","No") | H10: =IF(G10="Yes","Done","Not started")
A11: bajaj_platina_100_es_drum | B11: Bajaj | C11: Platina 100 | D11: ES Drum | E11: Commuter | F11: Mass-market ICE | G11: =IF(COUNTIFS(videos!$A:$A,A11,videos!$C:$C,"<>")>=1,"Yes","No") | H11: =IF(G11="Yes","Done","Not started")
A12: bajaj_platina_110_abs | B12: Bajaj | C12: Platina 110 | D12: ABS | E12: Commuter | F12: Mass-market ICE | G12: =IF(COUNTIFS(videos!$A:$A,A12,videos!$C:$C,"<>")>=1,"Yes","No") | H12: =IF(G12="Yes","Done","Not started")
A13: bajaj_freedom_125_cng_ng04_disc_led | B13: Bajaj | C13: Freedom 125 (CNG) | D13: NG04 Disc LED | E13: Commuter | F13: Mass-market ICE | G13: =IF(COUNTIFS(videos!$A:$A,A13,videos!$C:$C,"<>")>=1,"Yes","No") | H13: =IF(G13="Yes","Done","Not started")
... A253: zontes_350v_standard | B253: Zontes | C253: 350V | D253: Standard | E253: Cruiser | F253: Premium/Performance ICE | G253: =IF(COUNTIFS(videos!$A:$A,A253,videos!$C:$C,"<>")>=1,"Yes","No") | H253: =IF(G253="Yes","Done","Not started")

Sheet videos
A1: motorcycle_id | B1: youtube_video_id | C1: youtube_url | D1: title | E1: channel | F1: review_type | G1: language | H1: duration_seconds | I1: published_at | J1: view_count | K1: is_ground_truth | L1: transcript_status | M1: transcript_path | N1: added_by | O1: date_added | P1: notes | Q1: created_at | R1: updated_at
A2: aprilia_rs_457_standard | B2: -er9MuJBMgw | C2: https://youtu.be/-er9MuJBMgw?si=uDe4QtfF3HBnMc7M | D2: Aprilia RS 457 Road Review | The Million Dollar Question! | Sagar Sheldekar Official | E2: Sagar Sheldekar Official | F2: journalist | G2: English | H2: 485 | I2: 45391 | J2: 306243 | K2: Y | L2: done | M2: transcripts\aprilia_rs_457_standard.txt
A3: aprilia_rs_660_standard | B3: t8iLGr2_O_YvqFw3 | C3: https://youtu.be/5ZWQAi23Mxg?si=t8iLGr2_O_YvqFw3 | D3: 2021 Aprilia RS 660 Review | Daily Rider | E3: RevZilla | F3: journalist | G3: English | H3: 2029 | I3: 44282 | J3: 663715 | K3: Y | L3: done | M3: transcripts\aprilia_rs_660_standard.txt
A4: aprilia_tuono_660_standard | B4: XSCcViGWnNWKz7vV | C4: https://youtu.be/evHypf_f8BY?si=XSCcViGWnNWKz7vV | D4: 2021 Aprilia Tuono 660 First Ride Review | E4: RevZilla | F4: journalist | G4: English | H4: 213 | I4: 44292 | J4: 126460 | K4: Y | L4: done | M4: transcripts\aprilia_tuono_660_standard.txt
A5: aprilia_tuareg_660_standard | B5: htrRbDlZBdN47iJx | C5: https://youtu.be/Cs-TlgsCJZs?si=htrRbDlZBdN47iJx | D5: 2022 Aprilia Tuareg 660 Review | Daily Rider | E5: RevZilla | F5: journalist | G5: English | H5: 2029 | I5: 44695 | J5: 332243 | K5: Y | L5: done | M5: transcripts\aprilia_tuareg_660_standard.txt
A6: aprilia_rsv4_factory_standard | B6: GdKu8vkerjU3fmrh | C6: https://youtu.be/IsJ910DvBBQ?si=GdKu8vkerjU3fmrh | D6: 2025 Aprilia RSV4 Factory 1100 review | Noale's finest superbike yet | MCN | E6: MCN | F6: journalist | G6: English | H6: 954 | I6: 45779 | J6: 243537 | K6: Y | L6: failed
A7: aprilia_sr_125_standard | B7: nPztt0hHJMwndVPE | C7: https://youtu.be/H0Tx3cpKMkM?si=nPztt0hHJMwndVPE | D7: 2018 Aprilia SR125 - 5 Things you need to know | First Ride Review | E7: ZigWheels | F7: journalist | G7: English | H7: 394 | I7: 43170 | J7: 247486 | K7: Y | L7: done | M7: transcripts\aprilia_sr_125_standard.txt
A8: aprilia_sr_160_standard | B8: pfXVF2LrK2TwSVht | C8: https://youtu.be/CsmsD8TQh1M?si=pfXVF2LrK2TwSVht | D8: 2021 Aprilia SR 160 | What You Should Know | First Ride Review | PowerDrift | E8: PowerDrift | F8: journalist | G8: English | H8: 352 | I8: 44528 | J8: 163394 | K8: Y | L8: done | M8: transcripts\aprilia_sr_160_standard.txt
A9: aprilia_sxr_160_standard | B9: tE5uSnwpztT3sEbX | C9: https://youtu.be/RBbtw5cgY6Q?si=tE5uSnwpztT3sEbX | D9: 2020 Aprilia SXR 160 review - Maxi impact | First Ride | Autocar India | E9: Autocar India | F9: journalist | G9: English | H9: 506 | I9: 44186 | J9: 343694 | K9: Y | L9: done | M9: transcripts\aprilia_sxr_160_standard.txt
A10: bajaj_ct_110x_standard | B10: ObNmu-MPdsb9ydgv | C10: https://youtu.be/BgEbtgOoh74?si=ObNmu-MPdsb9ydgv | D10: Bajaj CT110 X BS6 - Detailed Review | Mileage | Comfort | Price | Rev Explorers | E10: Rev Explorers | F10: journalist | G10: English | H10: 568 | I10: 44398 | J10: 86546 | K10: Y | L10: done | M10: transcripts\bajaj_ct_110x_standard.txt
A11: bajaj_platina_100_es_drum | B11: LTaVMgQo2bRbYTWj | C11: https://youtu.be/4CflawOlGvo?si=LTaVMgQo2bRbYTWj | D11: MILEAGE KING | BAJAJ PLATINA 100 | DETAILED REVIEW | E11: REVSOUL | F11: journalist | G11: English | H11: 501 | I11: 46157 | J11: 666 | K11: Y | L11: done | M11: transcripts\bajaj_platina_100_es_drum.txt
A12: bajaj_platina_110_abs | B12: tg9lq7b6zr05em_F | C12: https://youtu.be/NC_iCF-c65o?si=tg9lq7b6zr05em_F | D12: 2025 Bajaj Platina 110 FI Detailed Review | SR Motoworld | E12: SR Motoworld | F12: journalist | G12: Hindi | H12: 936 | I12: 45783 | J12: 109340 | K12: Y | L12: done | M12: transcripts\bajaj_platina_110_abs.txt
A13: bajaj_freedom_125_cng_ng04_disc_led | B13: 4tr3FePIzA0il1iX | C13: https://youtu.be/HkEpyVD1t3k?si=4tr3FePIzA0il1iX | D13: Bajaj Freedom 125 CNG - The Only Review You Need! | PowerDrift | E13: PowerDrift | F13: journalist | G13: English | H13: 750 | I13: 45487 | J13: 210345 | K13: Y | L13: done | M13: transcripts\bajaj_freedom_125_cng_ng04_disc_led.txt
A14: bajaj_pulsar_125_carbon_single_seat | B14: jZMj9--hAXL313Is | C14: https://youtu.be/pu6PwreWdow?si=jZMj9--hAXL313Is | D14: New Bajaj Pulsar 125 and 150 - The legend reimagined for 2026 | First Look | Autocar India | E14: Autocar India | F14: journalist | G14: English | K14: Y | L14: done | M14: transcripts\bajaj_pulsar_125_carbon_single_seat.txt
A15: bajaj_pulsar_n125_standard | C15: https://youtu.be/6DC64U_myuU?si=H5Q0yR1I8_wfxQo_ | K15: Y | L15: done | M15: transcripts\bajaj_pulsar_n125_standard.txt
A16: bajaj_pulsar_ns125_standard | C16: https://youtu.be/GBSX_eF8WxM?si=DQ1ULpZ8FZd9Un7S | K16: Y | L16: done | M16: transcripts\bajaj_pulsar_ns125_standard.txt
A17: bajaj_pulsar_150_single_disc | C17: https://youtu.be/WjducW5cC5Q?si=ltKubp2lwA67IyCx | K17: Y | L17: done | M17: transcripts\bajaj_pulsar_150_single_disc.txt
A18: bajaj_pulsar_n160_dual_channel_abs | C18: https://youtu.be/6IbrAP24UbM?si=huQxN2GdHxckU4Uh | K18: Y | L18: done | M18: transcripts\bajaj_pulsar_n160_dual_channel_abs.txt
A19: bajaj_pulsar_ns160_dual_channel_abs | C19: https://youtu.be/fw1D12pgfnw?si=7SwfR9wylNc4rkIP | K19: Y | L19: done | M19: transcripts\bajaj_pulsar_ns160_dual_channel_abs.txt
A20: bajaj_pulsar_220f_standard | C20: https://youtu.be/T6suU5PHsoY?si=UAaYq1gQC6soDu8V | K20: Y | L20: done | M20: transcripts\bajaj_pulsar_220f_standard.txt
A21: bajaj_pulsar_n250_standard | C21: https://youtu.be/nn49ocqTrFg?si=Z5sEeIv2_q_8WcWi | K21: Y | L21: done | M21: transcripts\bajaj_pulsar_n250_standard.txt
A22: bajaj_pulsar_ns200_dual_channel_abs | C22: https://youtu.be/CI4V3zELoVU?si=cUjM1z43onT7-j1_ | K22: Y | L22: done | M22: transcripts\bajaj_pulsar_ns200_dual_channel_abs.txt
A23: bajaj_pulsar_rs200_dual_channel_abs | C23: https://youtu.be/N1ERYf8d-Gw?si=z7uS1G21wnWunYEY | K23: Y | L23: done | M23: transcripts\bajaj_pulsar_rs200_dual_channel_abs.txt
A24: bajaj_pulsar_ns400z_standard | C24: https://youtu.be/tX6b4cYI9rk?si=6_WYw_e0j-zzy5ng | K24: Y | L24: done | M24: transcripts\bajaj_pulsar_ns400z_standard.txt
A25: bajaj_avenger_street_160_standard | C25: https://youtu.be/f_08zAzXUnU?si=EPy0Ga549QiXKBca | K25: Y | L25: done | M25: transcripts\bajaj_avenger_street_160_standard.txt
A26: bajaj_avenger_cruise_220_standard | C26: https://youtu.be/z3JxRLUQd6E?si=P8KW_JMiGwZbS5yE | K26: Y | L26: done | M26: transcripts\bajaj_avenger_cruise_220_standard.txt
... A28: bajaj_dominar_400_standard | C28: https://youtu.be/d8Y9OQkTYVk?si=lIS79q9Cyjy3ukBE | K28: Y | L28: done | M28: transcripts\bajaj_dominar_400_standard.txt
A29: benelli_imperiale_400_standard | K29: Y | L29: pending
A30: benelli_trk_251_standard | K30: Y | L30: pending
A31: benelli_trk_502_std | K31: Y | L31: pending
A32: benelli_trk_502x_standard | K32: Y | L32: pending
A33: benelli_leoncino_500_standard | K33: Y | L33: pending
A34: benelli_502c_standard | K34: Y | L34: pending
A35: bmw_motorrad_g_310_r_standard | C35: https://youtu.be/IEFbORGxsjA?si=IKppLxVbGK0fSLqv | K35: Y | L35: done | M35: transcripts\bmw_motorrad_g_310_r_standard.txt
A36: bmw_motorrad_g_310_gs_standard | C36: https://youtu.be/PgqaOOQh6oQ?si=yAjg5gcgc1yZweBY | K36: Y | L36: done | M36: transcripts\bmw_motorrad_g_310_gs_standard.txt
A37: bmw_motorrad_g_310_rr_standard | C37: https://youtu.be/RtmRTBCBfOE?si=YJ4fV5nX-KL9SzYu | K37: Y | L37: done | M37: transcripts\bmw_motorrad_g_310_rr_standard.txt
A38: bmw_motorrad_f_900_xr_standard | C38: https://youtu.be/JVviu6Q6sn4?si=wcWX8-vZrpTNoOl7 | K38: Y | L38: done | M38: transcripts\bmw_motorrad_f_900_xr_standard.txt
A39: bmw_motorrad_s_1000_rr_standard | C39: https://youtu.be/3UB4YSzkRG8?si=vWfk8KytFrxTCLNv | K39: Y | L39: done | M39: transcripts\bmw_motorrad_s_1000_rr_standard.txt
A40: bmw_motorrad_s_1000_xr_standard | C40: https://youtu.be/poCotQmZVwk?si=v2IvNENsiprlvle- | K40: Y | L40: done | M40: transcripts\bmw_motorrad_s_1000_xr_standard.txt
A41: bmw_motorrad_m_1000_rr_standard | C41: https://youtu.be/JJ_MoPRSidQ?si=ZSjSZhxfhUpzoLI8 | K41: Y | L41: done | M41: transcripts\bmw_motorrad_m_1000_rr_standard.txt
...

Sheet Legend & Instructions
A1: How to use this tracker
A2: Scope: 1 ground-truth review video per motorcycle (252 total), to learn/build the RAG pipeline end-to-end.
A3: - 'motorcycles': one row per bike (reference table). motorcycle_id is a generated slug (brand_model_variant).
A4: - 'videos': one row per motorcycle_id. Fill in the YELLOW cells once you find a review video.
A6: To log a video:
A7: 1. Find the motorcycle_id in the 'videos' tab.
A8: 2. Fill: youtube_video_id, youtube_url, title, channel, review_type, language, duration_seconds, published_at, view_count, added_by, date_added, notes.
A9: 3. Leave transcript_status = 'pending' and transcript_path blank until the transcript pipeline runs.
A10: 4. is_ground_truth defaults to 'Y' since these are the hand-picked seed videos.
A12: The 'motorcycles' tab auto-updates 'video_collected' and 'status' as you fill the 'videos' tab.
A14: Later, if you want to expand to 2-3 videos/bike for cross-source verification, just add more rows to 'videos' with the same motorcycle_id (the sheet already supports many-to-one).

Sheet Progress Summary
A1: Metric | B1: Value
A2: Total motorcycles | B2: 252
A3: Videos collected | B3: =COUNTIF(motorcycles!G2:G253,"Yes")
A4: Not started | B4: =COUNTIF(motorcycles!G2:G253,"No")
A5: % Complete | B5: =B3/B2
